
---
## Ресурсы:
1. Данные конспекты выкладывались ранее [тут](https://vk.com/lambda_brain_not_null) (сейчас данные материалы уже не доступны)
2. Оригинал заметки лежит в этом репозитории по адресу `resource/lambda-brain-not-null/lambda-brain-not-null-21-exception-generation-is-evil.zip

---

На курсах АСД я периодически даю такой комментарий по стилю, что **нельзя использовать try catch (try except в Python) для непосредственного управления логикой программы**. Блоки try нужны либо для контроля за работой каких-то внешних ресурсов (файлы, сеть, ...), либо на этапе отладки, когда охватывается всё тело функции для более точной диагностики ошибки. В остальных случаях думайте над алгоритмом -- например, используйте if вместо try.  
Почему?

```java
public class DataParser
{
    public static int parseWithDefault(String input, int defaultValue)
    {
        try
        {
            return Integer.parseInt(input);
        }
        catch (NumberFormatException e)
        {
            // Обработка исключения как часть логики
            return defaultValue;
        }
    }
    ...
```

Исходно обработка исключений была добавлена в популярные языки для того, чтобы в случае, если что-то где-то пошло не так, программа элементарно не вылетала, теряя все данные. Например, в Common Lisp (код которого 60-летней давности нормально работает и сегодня), была введена псевдофункция ERROR, которая вызывалась в случае сбоев, и программист мог обратиться к ключевому слову ERRORSET, возвращавшему код ошибки. Постепенно и во всех популярных языках появилась фишка Structured Exception Handling (SEH). Теперь программисты получили возможность хоть как-то обрабатывать исключительные ситуации.

Обычно программа просто сохраняла все данные и сообщала пользователю о сбое, после чего закрывалась. Но в некоторых случаях (например, при некорректной работе с памятью) программа могла и продолжить свою работу.

И всё было бы хорошо до тех пор, пока не нашёлся некий умник, предложивший самостоятельно создавать условия исключений, и обрабатывать их по отдельности. А так как уровень мэйнстрима с каждым годом падает и падает, программисты принялись генерировать исключения, когда более подходящими были бы коды ошибок (например, если аргументы функции заданы некорректно), а то и вообще в безошибочных ситуациях -- просто чтобы сэкономить несколько строк кода.

Например, имеются три вложенные void-функции, в нижней обнаружена ошибочная ситуация, что делать? Рефакторить три функции, добавляя коды возврата, просто неохота. И вот в нижнюю функцию впиливается throw (raise в Python), а верхняя оборачивается try catch...

```java
public class NestedFunctionsExample
{
    
    public static void main(String[] args)
    {
        try
        {
            startProcessing();
        } catch (DataProcessingException e)
        {
            System.out.println("WTF??");
        }
    }

    // Уровень 1
    static void startProcessing() throws DataProcessingException
    {
        System.out.println("Начало обработки");
        prepareData(); // Вызов следующего уровня
        System.out.println("Обработка завершена успешно");
    }

    // Уровень 2
    static void prepareData() throws DataProcessingException
    {
        System.out.println("Подготовка данных");
        validateContent(); // Вызов следующего уровня
    }

    // Уровень 3 (нижний уровень с ошибкой)
    static void validateContent() throws DataProcessingException
    {
        System.out.println("Валидация данных");
        ... throw new DataProcessingException("Обнаружены некорректные данные");
        }
    }
}

// Кастомное исключение для бизнес-логики
class DataProcessingException extends Exception {
    public DataProcessingException(String message) {
        super(message);
    }
}
```

---

Самое страшное, что в Java выбрасывание исключений стало **идиоматическим**. При том, что оно, кстати, весьма критическое к ресурсам, потому что надо как следует пошарить по стеку вызовов в поисках обработчика, выполнить его (или несколько), затем перейти к finally, и в заключение вернуться в исходную точку. Однако от разработчика нередко ожидается, что он будет бросать исключения по любому поводу -- вместо return, если не найден элемент в массиве, после проверки параметров...

А после того, как SEH была добавлена в C++, куча популярных программ внезапно стала давать сбои и работать некорректно. Хорошо памятна история с iTunes, когда копию своей музыкальной базы данных приходилось делать каждый день. За утечками памяти можно было следить в реальном времени в диспетчере задач. В корпорациях уровня Microsoft эту проблему признали просто как данность, т.к. ничего не смогли с ней поделать, после чего в ряде языков (точнее, компиляторов и рантаймов) появилось подобие сборки мусора и подчистки памяти, потому что хоть какая-то семантика правильного управления памятью в них отсутствовала.

До throw в разработке властвовало **структурное программирование Дейкстры: у нас был условный оператор, цикл и функция с входом и выходом**. Ещё лет 50 назад появились первые автоматические анализаторы кода, потому что его поведение было чётко детерминированным; можно было отследить каждый путь и проверить каждое условие. Это был естественный поток управления. Хорошие разработчики находили ошибки без отладчика, просто методом пристального взгляда на код.

И вот появился throw, добавивший фактически вторую логику потока управления, но уже неестественную, непривычную, непредсказуемую и запутанную. Теперь такой код стало практически невозможно полноценно проверить, просто просмотрев его классическим code review. И если вы думаете, что throw и catch большинство разработчиков используют аккуратно и продуманно, то сильно ошибаетесь. Современные статические анализаторы в проектах даже среднего размера находят тысячи неоднозначных путей исполнения кода, поведение которого становится совершенно непредсказуемым. Можно гарантировать, что 98% программистов не будут писать код с той строгостью, которая подразумевается для безопасного использования throw.

---

```java
import java.util.Random;

public class ChaosController
{
    private static final Random RANDOM = new Random();

    // Уровень 1: Главный метод
    public static void main(String[] args)
    {
        try
        {
            processTransaction();
        } 
        catch (BusinessException e)
        {
            System.out.println("Общая ошибка: " + e.getMessage());
        }
    }

    // Уровень 2: Обработка транзакции
    static void processTransaction() throws BusinessException {
        try
        {
            if (RANDOM.nextBoolean())
            {
                validateUser();
            } 
            else 
	        {
                updateInventory();
            }
        } 
        catch (NetworkException | DatabaseException e)
        {
            throw new BusinessException("Ошибка операции");
        }
    }

    // Уровень 3: Валидация пользователя
    static void validateUser() throws NetworkException, DatabaseException
    {
        try
        {
            checkUserPermissions();
            logActivity();
        }
        catch (AuthorizationException e)
        {
            if (RANDOM.nextBoolean())
            {
                throw new NetworkException("Ошибка сети");
            }
            else
            {
                throw new DatabaseException("Ошибка БД");
            }
        }
    }

    // Уровень 4: Проверка прав
    static void checkUserPermissions() throws AuthorizationException
    {
        if (RANDOM.nextBoolean())
        {
            throw new AuthorizationException("Доступ запрещен");
        }
    }

    // Уровень 4: Обновление инвентаря
    static void updateInventory() throws DatabaseException
    {
        try
        {
            saveToDatabase();
        }
        catch (DatabaseException e)
        {
            if (RANDOM.nextBoolean())
            {
                retryOperation();
            }
            throw e;
        }
    }

    // Уровень 5: Повтор операции
    static void retryOperation() throws DatabaseException
    {
        if (RANDOM.nextBoolean())
        {
            throw new DatabaseException("Ошибка при повторе");
        }
    }

    // Уровень 5: Логирование
    static void logActivity()
    {
        if (RANDOM.nextBoolean())
        {
            throw new RuntimeException("Неожиданная ошибка логирования");
        }
    }
}

// Иерархия кастомных исключений
class BusinessException extends Exception
{
    BusinessException(String message) { super(message); }
}

class NetworkException extends BusinessException
{
    NetworkException(String message) { super(message); }
}

class DatabaseException extends BusinessException
{
    DatabaseException(String message) { super(message); }
}

class AuthorizationException extends Exception
{
    AuthorizationException(String message) { super(message); }
}
```

Слепое пробрасывание исключений, смешение checked и unchecked исключений, непредсказуемые ветвления, рекурсивные выбросы исключений, нарушение иерархии исключений, неполное логирование...

---

В идеале, лучше всего было бы удалить throw из всех языков программирования, а возможность создавать исключения оставить только рантайму и ОС. Но на практике, в рамках вашей компетенции вполне достаточно категорически запретить подчинённым разработчикам использовать это ключевое слово. Так произошло, например, в ряде команд Microsoft.

В самом крайнем случае, оборачивайте вызовы функций, выбрасывающих исключения, кодом try-catch прямо in place, локально в точках их вызовов, чтобы поток управления быстро возвращался к детерминированному режиму.  
Программирование снова становится предсказуемым, и мы вновь обретаем некоторую стабильность.

```java
import java.util.Random;

public class ControlledFlowExample
{
    private static final Random RANDOM = new Random();
    private static boolean retryFlag = false;

    public static void main(String[] args)
    {
        boolean success = false;
        int attempts = 0;
        
        // Детерминированный цикл обработки
        while (!success && attempts < 3)
        {
            try
            {
                attempts++;
                processTransaction();
                success = true;
                System.out.println("Операция завершена успешно");
            }
            catch (BusinessException e)
            {
                System.out.println("Попытка " + attempts + ": " + e.getMessage());
                handleError(e);
            }
        }
    }

    static void processTransaction() throws BusinessException
    {
        try
        {
            if (needValidation())
            {
                validateUser();
            }
            else
            {
                updateInventory();
            }
        }
        catch (AuthorizationException | DatabaseException e)
        {
            throw new BusinessException("Ошибка операции: " + e.getMessage(), e);
        }
    }

    static void validateUser() throws AuthorizationException {
        try
        {
            checkUserPermissions();
            logActivity();
        }
        catch (RuntimeException e)
        {
            System.err.println("Ошибка логирования: " + e.getMessage());
        }
    }

    static void checkUserPermissions() throws AuthorizationException
    {
        if (RANDOM.nextBoolean())
        {
            throw new AuthorizationException("Доступ запрещен");
        }
    }

    static void updateInventory() throws DatabaseException
    {
        try
        {
            saveToDatabase();
        }
        catch (DatabaseException e)
        {
            if (retryFlag)
            {
                System.out.println("Повторная попытка...");
                retryOperation();
            }
            throw e;
        }
    }

    static void saveToDatabase() throws DatabaseException
    {
        if (RANDOM.nextBoolean())
        {
            throw new DatabaseException("Ошибка соединения с БД");
        }
    }

    static void retryOperation() throws DatabaseException
    {
        if (RANDOM.nextBoolean())
        {
            throw new DatabaseException("Ошибка при повторе");
        }
    }

    static void logActivity()
    {
        if (RANDOM.nextBoolean())
        {
            throw new RuntimeException("Ошибка логирования");
        }
    }

    static boolean needValidation()
    {
        return RANDOM.nextBoolean();
    }

    static void handleError(BusinessException e)
    {
        retryFlag = e.getCause() instanceof DatabaseException;
    }
}

// Иерархия исключений
class BusinessException extends Exception
{
    BusinessException(String message, Throwable cause) { super(message, cause); }
}

class DatabaseException extends Exception
{
    DatabaseException(String message) { super(message); }
}

class AuthorizationException extends Exception
{
    AuthorizationException(String message) { super(message); }
}
```

_(хотя это всё равно плоховатый пример сам по себе)_  
Но как минимум мы получили локальную обработку исключений, контролируемые повторы операций, сохранение контекста ошибок, детерминированную обработку состояний, контроль побочных эффектов...

---

**Не используйте throw (raise ...). Прекратите это прямо сейчас.**